<?xml version="1.0"?>
<robot name="/home/ibtissam/Desktop/myrobot.urdf" xmlns:xacro="http://ros.org/wiki/xacro">
  <link name="base_link">
    <visual>
      <geometry>
        <box size="0.221 0.044 0.093"/>
      </geometry>
    </visual>
    <collision>
      <geometry>
        <box size="0.221 0.044 0.093"/>
      </geometry>
    </collision>
  </link>
  <link name="solid(5)">
    <visual>
      <geometry>
        <box size="0.0686 0.005 0.0534"/>
      </geometry>
    </visual>
    <collision>
      <geometry>
        <box size="0.0686 0.005 0.0534"/>
      </geometry>
    </collision>
  </link>
  <joint name="base_link_solid(5)_joint" type="fixed">
    <parent link="base_link"/>
    <child link="solid(5)"/>
    <origin xyz="0.01 0.023 0" rpy="0 0 0"/>
  </joint>
  <joint name="BLWheel" type="continuous">
    <parent link="base_link"/>
    <child link="solid(3)"/>
    <axis xyz="1.8041124e-16 1 -3.6732051e-06"/>
    <limit effort="10" velocity="10"/>
    <origin xyz="0.059999987 7.2647495e-08 -0.05" rpy="1.5708 -1.8041124e-16 -2.992343"/>
  </joint>
  <link name="solid(3)">
    <visual>
      <origin xyz="0 0 0" rpy="1.5707963 0 0"/>
      <geometry>
        <cylinder radius="0.033" length="0.025"/>
      </geometry>
    </visual>
    <collision>
      <origin xyz="0 0 0" rpy="1.5707963 0 0"/>
      <geometry>
        <cylinder radius="0.033" length="0.025"/>
      </geometry>
    </collision>
  </link>
  <joint name="BRWheel" type="continuous">
    <parent link="base_link"/>
    <child link="solid(2)"/>
    <axis xyz="5.551115e-17 1 -3.6732051e-06"/>
    <limit effort="10" velocity="10"/>
    <origin xyz="-0.059999928 2.5968236e-09 -0.05" rpy="1.5708 -5.551115e-17 1.6061519"/>
  </joint>
  <link name="solid(2)">
    <visual>
      <origin xyz="0 0 0" rpy="1.5707963 0 0"/>
      <geometry>
        <cylinder radius="0.033" length="0.025"/>
      </geometry>
    </visual>
    <collision>
      <origin xyz="0 0 0" rpy="1.5707963 0 0"/>
      <geometry>
        <cylinder radius="0.033" length="0.025"/>
      </geometry>
    </collision>
  </link>
  <joint name="FRWheel" type="continuous">
    <parent link="base_link"/>
    <child link="solid(1)"/>
    <axis xyz="-2.220446e-16 1 -3.6732051e-06"/>
    <limit effort="10" velocity="10"/>
    <origin xyz="-0.060000055 -5.0040114e-08 0.05" rpy="1.5708 2.220446e-16 2.3201282"/>
  </joint>
  <link name="solid(1)">
    <visual>
      <origin xyz="0 0 0" rpy="1.5707963 0 0"/>
      <geometry>
        <cylinder radius="0.033" length="0.025"/>
      </geometry>
    </visual>
    <collision>
      <origin xyz="0 0 0" rpy="1.5707963 0 0"/>
      <geometry>
        <cylinder radius="0.033" length="0.025"/>
      </geometry>
    </collision>
  </link>
  <joint name="FLWheel" type="continuous">
    <parent link="base_link"/>
    <child link="solid"/>
    <axis xyz="1.6653345e-16 1 -3.6732051e-06"/>
    <limit effort="10" velocity="10"/>
    <origin xyz="0.060000055 -4.7750703e-08 0.05" rpy="1.5708 -1.6653345e-16 -2.2783635"/>
  </joint>
  <link name="solid">
    <visual>
      <origin xyz="0 0 0" rpy="1.5707963 0 0"/>
      <geometry>
        <cylinder radius="0.033" length="0.025"/>
      </geometry>
    </visual>
    <collision>
      <origin xyz="0 0 0" rpy="1.5707963 0 0"/>
      <geometry>
        <cylinder radius="0.033" length="0.025"/>
      </geometry>
    </collision>
  </link>
</robot>
